<robot name="ALFRED">
 
<link name="ground_ref"/>

  <!-- Main Body -->
<link name="base_link">
  <visual>
  <origin rpy="0 0 0" xyz="0 0 0"/>
  <geometry>
  <box size="0.6 0.4 0.2"/>
  </geometry>
  <material name="blue"/>
  </visual>
  <collision>
  <geometry>
  <box size="0.6 0.4 0.2"/>
  </geometry>
  </collision>
  <inertial>
  <mass value="5.0"/>
  <inertia ixx="0.02" ixy="0.0" ixz="0.0" iyy="0.03" iyz="0.0" izz="0.04"/>
  </inertial>
</link>
 
  <!-- Left Wheel -->
<link name="left_wheel">
<visual>
<geometry>
<cylinder radius="0.15" length="0.05"/>
</geometry>
<material name="black"/>
</visual>
<collision>
<geometry>
<cylinder radius="0.15" length="0.05"/>
</geometry>
</collision>
<inertial>
<mass value="0.5"/>
<inertia ixx="0.001" ixy="0.0" ixz="0.0" iyy="0.001" iyz="0.0" izz="0.001"/>
</inertial>
</link>
 
  <!-- Right Wheel -->
<link name="right_wheel">
<visual>
<geometry>
<cylinder radius="0.05" length="0.03"/>
</geometry>
<material name="black"/>
</visual>
<collision>
<geometry>
<cylinder radius="0.05" length="0.03"/>
</geometry>
</collision>
<inertial>
<mass value="0.5"/>
<inertia ixx="0.001" ixy="0.0" ixz="0.0" iyy="0.001" iyz="0.0" izz="0.001"/>
</inertial>
</link>
 
  <!-- Caster Wheel 1 -->
<link name="caster_wheel_1">
<visual>
<geometry>
<sphere radius="0.03"/>
</geometry>
<material name="gray"/>
</visual>
<collision>
<geometry>
<sphere radius="0.03"/>
</geometry>
</collision>
<inertial>
<mass value="0.2"/>
<inertia ixx="0.0001" ixy="0.0" ixz="0.0" iyy="0.0001" iyz="0.0" izz="0.0001"/>
</inertial>
</link>
 
  <!-- Caster Wheel 2 -->
<link name="caster_wheel_2">
<visual>
<geometry>
<sphere radius="0.03"/>
</geometry>
<material name="gray"/>
</visual>
<collision>
<geometry>
<sphere radius="0.03"/>
</geometry>
</collision>
<inertial>
<mass value="0.2"/>
<inertia ixx="0.0001" ixy="0.0" ixz="0.0" iyy="0.0001" iyz="0.0" izz="0.0001"/>
</inertial>
</link>
 
  <!-- Joints -->

<joint name="base_joint" type="fixed">
  <parent link="ground_ref"/>
  <child link="base_link"/>
  <origin rpy="0 0 0" xyz="0 0 0.2"/>

</joint>

<!-- Left Wheel Joint -->
<joint name="left_wheel_joint" type="continuous">
<parent link="base_link"/>
<child link="left_wheel"/>
<origin xyz="-0.2 0.15 -0.05" rpy="0 1.5708 0"/>
<axis xyz="0 0 1"/>
</joint>
 
  <!-- Right Wheel Joint -->
<joint name="right_wheel_joint" type="continuous">
<parent link="base_link"/>
<child link="right_wheel"/>
<origin xyz="-0.2 -0.15 -0.05" rpy="0 1.5708 0"/>
<axis xyz="0 0 1"/>
</joint>
 
  <!-- Caster Wheel 1 Joint -->
<joint name="caster_wheel_1_joint" type="fixed">
<parent link="base_link"/>
<child link="caster_wheel_1"/>
<origin xyz="0.2 0.1 -0.1" rpy="0 0 0"/>
</joint>
 
  <!-- Caster Wheel 2 Joint -->
<joint name="caster_wheel_2_joint" type="fixed">
<parent link="base_link"/>
<child link="caster_wheel_2"/>
<origin xyz="0.2 -0.1 -0.1" rpy="0 0 0"/>
</joint>
 
</robot>
